Workbook

Sheet Resumen
C2: Actual | D2: Actual | E2: Actual | F2: Actual | G2: Actual | H2: Actual | I2: Actual | J2: Actual | K2: Actual | L2: Actual | M2: Actual | N2: Actual
B3: P&G | C3: 1 | D3: =C3+1 -> 2 | E3: =D3+1 -> 3 | F3: =E3+1 -> 4 | G3: =F3+1 -> 5 | H3: =G3+1 -> 6 | I3: =H3+1 -> 7 | J3: =I3+1 -> 8 | K3: =J3+1 -> 9 | ... N3: =M3+1 -> 12 | O3: YTD
B4: Ingresos (facturado) | C4: =SUMIFS(CxC!$H$11:$H$51,CxC!$T$11:$T$51,C$3) -> 0 | D4: =SUMIFS(CxC!$H$11:$H$51,CxC!$T$11:$T$51,D$3) -> 0 | E4: =SUMIFS(CxC!$H$11:$H$51,CxC!$T$11:$T$51,E$3) -> 0 | F4: =SUMIFS(CxC!$H$11:$H$51,CxC!$T$11:$T$51,F$3) -> 39970574 | G4: =SUMIFS(CxC!$H$11:$H$51,CxC!$T$11:$T$51,G$3) -> 257438378 | H4: =SUMIFS(CxC!$H$11:$H$51,CxC!$T$11:$T$51,H$3) -> 0 | I4: =SUMIFS(CxC!$H$11:$H$51,CxC!$T$11:$T$51,I$3) -> 42623908 | J4: =SUMIFS(CxC!$H$11:$H$51,CxC!$T$11:$T$51,J$3) -> 62704578 | ... N4: =SUMIFS(CxC!$H$11:$H$51,CxC!$T$11:$T$51,N$3) -> 0 | O4: =+SUM(C4:N4) -> 486681543
B5: Costo Ventas | C5: =-SUMIFS(CxP!$K$6:$K$163,CxP!$X$6:$X$163,$B5,CxP!$Y$6:$Y$163,"Si",CxP!$B$6:$B$163,">="&DATE(2026,C$3,1),CxP!$B$6:$B$163,"<="&EOMONTH(DATE(2026,C$3,1),0))-SUMIFS(CxP!$M$6:$M$163,CxP!$X$6:$X$163,$B5,CxP!$Y$6:$Y$163,"Si",CxP!$B$6:$B$163,">="&DATE(2026,C$3,1),CxP!$B$6:$B$163,"<="&EOMONTH(DATE(2026,C$3,1),0))+SUMIFS('Extractos bancarios - Manglar'!$C:$C,'Extractos bancarios - Manglar'!$G:$G,$B5,'Extractos bancarios - Manglar'!$L:$L,C$3,'Extractos bancarios - Manglar'!$M:$M,"")-SUMIFS('Extractos bancarios - Manglar'!$C:$C,'Extractos bancarios - Manglar'!$G:$G,$B5,'Extractos bancarios - Manglar'!$L:$L,C$3,'Extractos bancarios - Manglar'!$M:$M,"",'Extractos bancarios - Manglar'!$K:$K,"Si")*0.19/1.19 -> 0 | D5: =-SUMIFS(CxP!$K$6:$K$163,CxP!$X$6:$X$163,$B5,CxP!$Y$6:$Y$163,"Si",CxP!$B$6:$B$163,">="&DATE(2026,D$3,1),CxP!$B$6:$B$163,"<="&EOMONTH(DATE(2026,D$3,1),0))-SUMIFS(CxP!$M$6:$M$163,CxP!$X$6:$X$163,$B5,CxP!$Y$6:$Y$163,"Si",CxP!$B$6:$B$163,">="&DATE(2026,D$3,1),CxP!$B$6:$B$163,"<="&EOMONTH(DATE(2026,D$3,1),0))+SUMIFS('Extractos bancarios - Manglar'!$C:$C,'Extractos bancarios - Manglar'!$G:$G,$B5,'Extractos bancarios - Manglar'!$L:$L,D$3,'Extractos bancarios - Manglar'!$M:$M,"")-SUMIFS('Extractos bancarios - Manglar'!$C:$C,'Extractos bancarios - Manglar'!$G:$G,$B5,'Extractos bancarios - Manglar'!$L:$L,D$3,'Extractos bancarios - Manglar'!$M:$M,"",'Extractos bancarios - Manglar'!$K:$K,"Si")*0.19/1.19 -> 0 | E5: =-SUMIFS(CxP!$K$6:$K$163,CxP!$X$6:$X$163,$B5,CxP!$Y$6:$Y$163,"Si",CxP!$B$6:$B$163,">="&DATE(2026,E$3,1),CxP!$B$6:$B$163,"<="&EOMONTH(DATE(2026,E$3,1),0))-SUMIFS(CxP!$M$6:$M$163,CxP!$X$6:$X$163,$B5,CxP!$Y$6:$Y$163,"Si",CxP!$B$6:$B$163,">="&DATE(2026,E$3,1),CxP!$B$6:$B$163,"<="&EOMONTH(DATE(2026,E$3,1),0))+SUMIFS('Extractos bancarios - Manglar'!$C:$C,'Extractos bancarios - Manglar'!$G:$G,$B5,'Extractos bancarios - Manglar'!$L:$L,E$3,'Extractos bancarios - Manglar'!$M:$M,"")-SUMIFS('Extractos bancarios - Manglar'!$C:$C,'Extractos bancarios - Manglar'!$G:$G,$B5,'Extractos bancarios - Manglar'!$L:$L,E$3,'Extractos bancarios - Manglar'!$M:$M,"",'Extractos bancarios - Manglar'!$K:$K,"Si")*0.19/1.19 -> -96100 | F5: =-SUMIFS(CxP!$K$6:$K$163,CxP!$X$6:$X$163,$B5,CxP!$Y$6:$Y$163,"Si",CxP!$B$6:$B$163,">="&DATE(2026,F$3,1),CxP!$B$6:$B$163,"<="&EOMONTH(DATE(2026,F$3,1),0))-SUMIFS(CxP!$M$6:$M$163,CxP!$X$6:$X$163,$B5,CxP!$Y$6:$Y$163,"Si",CxP!$B$6:$B$163,">="&DATE(2026,F$3,1),CxP!$B$6:$B$163,"<="&EOMONTH(DATE(2026,F$3,1),0))+SUMIFS('Extractos bancarios - Manglar'!$C:$C,'Extractos bancarios - Manglar'!$G:$G,$B5,'Extractos bancarios - Manglar'!$L:$L,F$3,'Extractos bancarios - Manglar'!$M:$M,"")-SUMIFS('Extractos bancarios - Manglar'!$C:$C,'Extractos bancarios - Manglar'!$G:$G,$B5,'Extractos bancarios - Manglar'!$L:$L,F$3,'Extractos bancarios - Manglar'!$M:$M,"",'Extractos bancarios - Manglar'!$K:$K,"Si")*0.19/1.19 -> -11807899 | G5: =-SUMIFS(CxP!$K$6:$K$163,CxP!$X$6:$X$163,$B5,CxP!$Y$6:$Y$163,"Si",CxP!$B$6:$B$163,">="&DATE(2026,G$3,1),CxP!$B$6:$B$163,"<="&EOMONTH(DATE(2026,G$3,1),0))-SUMIFS(CxP!$M$6:$M$163,CxP!$X$6:$X$163,$B5,CxP!$Y$6:$Y$163,"Si",CxP!$B$6:$B$163,">="&DATE(2026,G$3,1),CxP!$B$6:$B$163,"<="&EOMONTH(DATE(2026,G$3,1),0))+SUMIFS('Extractos bancarios - Manglar'!$C:$C,'Extractos bancarios - Manglar'!$G:$G,$B5,'Extractos bancarios - Manglar'!$L:$L,G$3,'Extractos bancarios - Manglar'!$M:$M,"")-SUMIFS('Extractos bancarios - Manglar'!$C:$C,'Extractos bancarios - Manglar'!$G:$G,$B5,'Extractos bancarios - Manglar'!$L:$L,G$3,'Extractos bancarios - Manglar'!$M:$M,"",'Extractos bancarios - Manglar'!$K:$K,"Si")*0.19/1.19 -> -12820269 | H5: =-SUMIFS(CxP!$K$6:$K$163,CxP!$X$6:$X$163,$B5,CxP!$Y$6:$Y$163,"Si",CxP!$B$6:$B$163,">="&DATE(2026,H$3,1),CxP!$B$6:$B$163,"<="&EOMONTH(DATE(2026,H$3,1),0))-SUMIFS(CxP!$M$6:$M$163,CxP!$X$6:$X$163,$B5,CxP!$Y$6:$Y$163,"Si",CxP!$B$6:$B$163,">="&DATE(2026,H$3,1),CxP!$B$6:$B$163,"<="&EOMONTH(DATE(2026,H$3,1),0))+SUMIFS('Extractos bancarios - Manglar'!$C:$C,'Extractos bancarios - Manglar'!$G:$G,$B5,'Extractos bancarios - Manglar'!$L:$L,H$3,'Extractos bancarios - Manglar'!$M:$M,"")-SUMIFS('Extractos bancarios - Manglar'!$C:$C,'Extractos bancarios - Manglar'!$G:$G,$B5,'Extractos bancarios - Manglar'!$L:$L,H$3,'Extractos bancarios - Manglar'!$M:$M,"",'Extractos bancarios - Manglar'!$K:$K,"Si")*0.19/1.19 -> -1.6523143e+08 | I5: =-SUMIFS(CxP!$K$6:$K$163,CxP!$X$6:$X$163,$B5,CxP!$Y$6:$Y$163,"Si",CxP!$B$6:$B$163,">="&DATE(2026,I$3,1),CxP!$B$6:$B$163,"<="&EOMONTH(DATE(2026,I$3,1),0))-SUMIFS(CxP!$M$6:$M$163,CxP!$X$6:$X$163,$B5,CxP!$Y$6:$Y$163,"Si",CxP!$B$6:$B$163,">="&DATE(2026,I$3,1),CxP!$B$6:$B$163,"<="&EOMONTH(DATE(2026,I$3,1),0))+SUMIFS('Extractos bancarios - Manglar'!$C:$C,'Extractos bancarios - Manglar'!$G:$G,$B5,'Extractos bancarios - Manglar'!$L:$L,I$3,'Extractos bancarios - Manglar'!$M:$M,"")-SUMIFS('Extractos bancarios - Manglar'!$C:$C,'Extractos bancarios - Manglar'!$G:$G,$B5,'Extractos bancarios - Manglar'!$L:$L,I$3,'Extractos bancarios - Manglar'!$M:$M,"",'Extractos bancarios - Manglar'!$K:$K,"Si")*0.19/1.19 -> -39675772 | J5: =-SUMIFS(CxP!$K$6:$K$163,CxP!$X$6:$X$163,$B5,CxP!$Y$6:$Y$163,"Si",CxP!$B$6:$B$163,">="&DATE(2026,J$3,1),CxP!$B$6:$B$163,"<="&EOMONTH(DATE(2026,J$3,1),0))-SUMIFS(CxP!$M$6:$M$163,CxP!$X$6:$X$163,$B5,CxP!$Y$6:$Y$163,"Si",CxP!$B$6:$B$163,">="&DATE(2026,J$3,1),CxP!$B$6:$B$163,"<="&EOMONTH(DATE(2026,J$3,1),0))+SUMIFS('Extractos bancarios - Manglar'!$C:$C,'Extractos bancarios - Manglar'!$G:$G,$B5,'Extractos bancarios - Manglar'!$L:$L,J$3,'Extractos bancarios - Manglar'!$M:$M,"")-SUMIFS('Extractos bancarios - Manglar'!$C:$C,'Extractos bancarios - Manglar'!$G:$G,$B5,'Extractos bancarios - Manglar'!$L:$L,J$3,'Extractos bancarios - Manglar'!$M:$M,"",'Extractos bancarios - Manglar'!$K:$K,"Si")*0.19/1.19 -> -18764243 | ... N5: =-SUMIFS(CxP!$K$6:$K$163,CxP!$X$6:$X$163,$B5,CxP!$Y$6:$Y$163,"Si",CxP!$B$6:$B$163,">="&DATE(2026,N$3,1),CxP!$B$6:$B$163,"<="&EOMONTH(DATE(2026,N$3,1),0))-SUMIFS(CxP!$M$6:$M$163,CxP!$X$6:$X$163,$B5,CxP!$Y$6:$Y$163,"Si",CxP!$B$6:$B$163,">="&DATE(2026,N$3,1),CxP!$B$6:$B$163,"<="&EOMONTH(DATE(2026,N$3,1),0))+SUMIFS('Extractos bancarios - Manglar'!$C:$C,'Extractos bancarios - Manglar'!$G:$G,$B5,'Extractos bancarios - Manglar'!$L:$L,N$3,'Extractos bancarios - Manglar'!$M:$M,"")-SUMIFS('Extractos bancarios - Manglar'!$C:$C,'Extractos bancarios - Manglar'!$G:$G,$B5,'Extractos bancarios - Manglar'!$L:$L,N$3,'Extractos bancarios - Manglar'!$M:$M,"",'Extractos bancarios - Manglar'!$K:$K,"Si")*0.19/1.19 -> 0 | O5: =+SUM(C5:N5) -> -3.5685309e+08
B6: Margen Bruto | C6: =+C4+C5 -> 0 | D6: =+D4+D5 -> 0 | E6: =+E4+E5 -> -96100 | F6: =+F4+F5 -> 28162675 | G6: =+G4+G5 -> 2.4461811e+08 | H6: =+H4+H5 -> -1.6523143e+08 | I6: =+I4+I5 -> 2948135.7 | J6: =+J4+J5 -> 43940335 | ... N6: =+N4+N5 -> 0 | O6: =+SUM(C6:N6) -> 1.2982845e+08
B7: Margen Bruto % | C7: =IFERROR(+C6/C$4,"-") -> - | D7: =IFERROR(+D6/D$4,"-") -> - | E7: =IFERROR(+E6/E$4,"-") -> - | F7: =IFERROR(+F6/F$4,"-") -> 0.70458521 | G7: =IFERROR(+G6/G$4,"-") -> 0.95020063 | H7: =IFERROR(+H6/H$4,"-") -> - | I7: =IFERROR(+I6/I$4,"-") -> 0.069166246 | J7: =IFERROR(+J6/J$4,"-") -> 0.70075163 | ... O7: =IFERROR(+O6/O$4,"-") -> 0.26676264
B8: Otros Ingresos | C8: =(SUMIFS('Extractos bancarios - Manglar'!$C:$C,'Extractos bancarios - Manglar'!$G:$G,$B8,'Extractos bancarios - Manglar'!$L:$L,C$3,'Extractos bancarios - Manglar'!$K:$K,"Si")/1.19)+SUMIFS('Extractos bancarios - Manglar'!$C:$C,'Extractos bancarios - Manglar'!$G:$G,$B8,'Extractos bancarios - Manglar'!$L:$L,C$3,'Extractos bancarios - Manglar'!$K:$K,"No") -> 0 | D8: =(SUMIFS('Extractos bancarios - Manglar'!$C:$C,'Extractos bancarios - Manglar'!$G:$G,$B8,'Extractos bancarios - Manglar'!$L:$L,D$3,'Extractos bancarios - Manglar'!$K:$K,"Si")/1.19)+SUMIFS('Extractos bancarios - Manglar'!$C:$C,'Extractos bancarios - Manglar'!$G:$G,$B8,'Extractos bancarios - Manglar'!$L:$L,D$3,'Extractos bancarios - Manglar'!$K:$K,"No") -> 0 | E8: =(SUMIFS('Extractos bancarios - Manglar'!$C:$C,'Extractos bancarios - Manglar'!$G:$G,$B8,'Extractos bancarios - Manglar'!$L:$L,E$3,'Extractos bancarios - Manglar'!$K:$K,"Si")/1.19)+SUMIFS('Extractos bancarios - Manglar'!$C:$C,'Extractos bancarios - Manglar'!$G:$G,$B8,'Extractos bancarios - Manglar'!$L:$L,E$3,'Extractos bancarios - Manglar'!$K:$K,"No") -> 0 | F8: =(SUMIFS('Extractos bancarios - Manglar'!$C:$C,'Extractos bancarios - Manglar'!$G:$G,$B8,'Extractos bancarios - Manglar'!$L:$L,F$3,'Extractos bancarios - Manglar'!$K:$K,"Si")/1.19)+SUMIFS('Extractos bancarios - Manglar'!$C:$C,'Extractos bancarios - Manglar'!$G:$G,$B8,'Extractos bancarios - Manglar'!$L:$L,F$3,'Extractos bancarios - Manglar'!$K:$K,"No") -> 0 | G8: =(SUMIFS('Extractos bancarios - Manglar'!$C:$C,'Extractos bancarios - Manglar'!$G:$G,$B8,'Extractos bancarios - Manglar'!$L:$L,G$3,'Extractos bancarios - Manglar'!$K:$K,"Si")/1.19)+SUMIFS('Extractos bancarios - Manglar'!$C:$C,'Extractos bancarios - Manglar'!$G:$G,$B8,'Extractos bancarios - Manglar'!$L:$L,G$3,'Extractos bancarios - Manglar'!$K:$K,"No") -> 0 | H8: =(SUMIFS('Extractos bancarios - Manglar'!$C:$C,'Extractos bancarios - Manglar'!$G:$G,$B8,'Extractos bancarios - Manglar'!$L:$L,H$3,'Extractos bancarios - Manglar'!$K:$K,"Si")/1.19)+SUMIFS('Extractos bancarios - Manglar'!$C:$C,'Extractos bancarios - Manglar'!$G:$G,$B8,'Extractos bancarios - Manglar'!$L:$L,H$3,'Extractos bancarios - Manglar'!$K:$K,"No") -> 0 | I8: =(SUMIFS('Extractos bancarios - Manglar'!$C:$C,'Extractos bancarios - Manglar'!$G:$G,$B8,'Extractos bancarios - Manglar'!$L:$L,I$3,'Extractos bancarios - Manglar'!$K:$K,"Si")/1.19)+SUMIFS('Extractos bancarios - Manglar'!$C:$C,'Extractos bancarios - Manglar'!$G:$G,$B8,'Extractos bancarios - Manglar'!$L:$L,I$3,'Extractos bancarios - Manglar'!$K:$K,"No") -> 0 | J8: =(SUMIFS('Extractos bancarios - Manglar'!$C:$C,'Extractos bancarios - Manglar'!$G:$G,$B8,'Extractos bancarios - Manglar'!$L:$L,J$3,'Extractos bancarios - Manglar'!$K:$K,"Si")/1.19)+SUMIFS('Extractos bancarios - Manglar'!$C:$C,'Extractos bancarios - Manglar'!$G:$G,$B8,'Extractos bancarios - Manglar'!$L:$L,J$3,'Extractos bancarios - Manglar'!$K:$K,"No") -> 0 | ... N8: =(SUMIFS('Extractos bancarios - Manglar'!$C:$C,'Extractos bancarios - Manglar'!$G:$G,$B8,'Extractos bancarios - Manglar'!$L:$L,N$3,'Extractos bancarios - Manglar'!$K:$K,"Si")/1.19)+SUMIFS('Extractos bancarios - Manglar'!$C:$C,'Extractos bancarios - Manglar'!$G:$G,$B8,'Extractos bancarios - Manglar'!$L:$L,N$3,'Extractos bancarios - Manglar'!$K:$K,"No") -> 0 | O8: =+SUM(C8:N8) -> 0
B9: Costos Fijos | C9: =-SUMIFS(CxP!$K$6:$K$163,CxP!$X$6:$X$163,$B9,CxP!$Y$6:$Y$163,"Si",CxP!$B$6:$B$163,">="&DATE(2026,C$3,1),CxP!$B$6:$B$163,"<="&EOMONTH(DATE(2026,C$3,1),0))-SUMIFS(CxP!$M$6:$M$163,CxP!$X$6:$X$163,$B9,CxP!$Y$6:$Y$163,"Si",CxP!$B$6:$B$163,">="&DATE(2026,C$3,1),CxP!$B$6:$B$163,"<="&EOMONTH(DATE(2026,C$3,1),0))+SUMIFS('Extractos bancarios - Manglar'!$C:$C,'Extractos bancarios - Manglar'!$G:$G,$B9,'Extractos bancarios - Manglar'!$L:$L,C$3,'Extractos bancarios - Manglar'!$M:$M,"")-SUMIFS('Extractos bancarios - Manglar'!$C:$C,'Extractos bancarios - Manglar'!$G:$G,$B9,'Extractos bancarios - Manglar'!$L:$L,C$3,'Extractos bancarios - Manglar'!$M:$M,"",'Extractos bancarios - Manglar'!$K:$K,"Si")*0.19/1.19 -> 0 | D9: =-SUMIFS(CxP!$K$6:$K$163,CxP!$X$6:$X$163,$B9,CxP!$Y$6:$Y$163,"Si",CxP!$B$6:$B$163,">="&DATE(2026,D$3,1),CxP!$B$6:$B$163,"<="&EOMONTH(DATE(2026,D$3,1),0))-SUMIFS(CxP!$M$6:$M$163,CxP!$X$6:$X$163,$B9,CxP!$Y$6:$Y$163,"Si",CxP!$B$6:$B$163,">="&DATE(2026,D$3,1),CxP!$B$6:$B$163,"<="&EOMONTH(DATE(2026,D$3,1),0))+SUMIFS('Extractos bancarios - Manglar'!$C:$C,'Extractos bancarios - Manglar'!$G:$G,$B9,'Extractos bancarios - Manglar'!$L:$L,D$3,'Extractos bancarios - Manglar'!$M:$M,"")-SUMIFS('Extractos bancarios - Manglar'!$C:$C,'Extractos bancarios - Manglar'!$G:$G,$B9,'Extractos bancarios - Manglar'!$L:$L,D$3,'Extractos bancarios - Manglar'!$M:$M,"",'Extractos bancarios - Manglar'!$K:$K,"Si")*0.19/1.19 -> 0 | E9: =-SUMIFS(CxP!$K$6:$K$163,CxP!$X$6:$X$163,$B9,CxP!$Y$6:$Y$163,"Si",CxP!$B$6:$B$163,">="&DATE(2026,E$3,1),CxP!$B$6:$B$163,"<="&EOMONTH(DATE(2026,E$3,1),0))-SUMIFS(CxP!$M$6:$M$163,CxP!$X$6:$X$163,$B9,CxP!$Y$6:$Y$163,"Si",CxP!$B$6:$B$163,">="&DATE(2026,E$3,1),CxP!$B$6:$B$163,"<="&EOMONTH(DATE(2026,E$3,1),0))+SUMIFS('Extractos bancarios - Manglar'!$C:$C,'Extractos bancarios - Manglar'!$G:$G,$B9,'Extractos bancarios - Manglar'!$L:$L,E$3,'Extractos bancarios - Manglar'!$M:$M,"")-SUMIFS('Extractos bancarios - Manglar'!$C:$C,'Extractos bancarios - Manglar'!$G:$G,$B9,'Extractos bancarios - Manglar'!$L:$L,E$3,'Extractos bancarios - Manglar'!$M:$M,"",'Extractos bancarios - Manglar'!$K:$K,"Si")*0.19/1.19 -> -18050 | F9: =-SUMIFS(CxP!$K$6:$K$163,CxP!$X$6:$X$163,$B9,CxP!$Y$6:$Y$163,"Si",CxP!$B$6:$B$163,">="&DATE(2026,F$3,1),CxP!$B$6:$B$163,"<="&EOMONTH(DATE(2026,F$3,1),0))-SUMIFS(CxP!$M$6:$M$163,CxP!$X$6:$X$163,$B9,CxP!$Y$6:$Y$163,"Si",CxP!$B$6:$B$163,">="&DATE(2026,F$3,1),CxP!$B$6:$B$163,"<="&EOMONTH(DATE(2026,F$3,1),0))+SUMIFS('Extractos bancarios - Manglar'!$C:$C,'Extractos bancarios - Manglar'!$G:$G,$B9,'Extractos bancarios - Manglar'!$L:$L,F$3,'Extractos bancarios - Manglar'!$M:$M,"")-SUMIFS('Extractos bancarios - Manglar'!$C:$C,'Extractos bancarios - Manglar'!$G:$G,$B9,'Extractos bancarios - Manglar'!$L:$L,F$3,'Extractos bancarios - Manglar'!$M:$M,"",'Extractos bancarios - Manglar'!$K:$K,"Si")*0.19/1.19 -> -18050 | G9: =-SUMIFS(CxP!$K$6:$K$163,CxP!$X$6:$X$163,$B9,CxP!$Y$6:$Y$163,"Si",CxP!$B$6:$B$163,">="&DATE(2026,G$3,1),CxP!$B$6:$B$163,"<="&EOMONTH(DATE(2026,G$3,1),0))-SUMIFS(CxP!$M$6:$M$163,CxP!$X$6:$X$163,$B9,CxP!$Y$6:$Y$163,"Si",CxP!$B$6:$B$163,">="&DATE(2026,G$3,1),CxP!$B$6:$B$163,"<="&EOMONTH(DATE(2026,G$3,1),0))+SUMIFS('Extractos bancarios - Manglar'!$C:$C,'Extractos bancarios - Manglar'!$G:$G,$B9,'Extractos bancarios - Manglar'!$L:$L,G$3,'Extractos bancarios - Manglar'!$M:$M,"")-SUMIFS('Extractos bancarios - Manglar'!$C:$C,'Extractos bancarios - Manglar'!$G:$G,$B9,'Extractos bancarios - Manglar'!$L:$L,G$3,'Extractos bancarios - Manglar'!$M:$M,"",'Extractos bancarios - Manglar'!$K:$K,"Si")*0.19/1.19 -> -18050 | H9: =-SUMIFS(CxP!$K$6:$K$163,CxP!$X$6:$X$163,$B9,CxP!$Y$6:$Y$163,"Si",CxP!$B$6:$B$163,">="&DATE(2026,H$3,1),CxP!$B$6:$B$163,"<="&EOMONTH(DATE(2026,H$3,1),0))-SUMIFS(CxP!$M$6:$M$163,CxP!$X$6:$X$163,$B9,CxP!$Y$6:$Y$163,"Si",CxP!$B$6:$B$163,">="&DATE(2026,H$3,1),CxP!$B$6:$B$163,"<="&EOMONTH(DATE(2026,H$3,1),0))+SUMIFS('Extractos bancarios - Manglar'!$C:$C,'Extractos bancarios - Manglar'!$G:$G,$B9,'Extractos bancarios - Manglar'!$L:$L,H$3,'Extractos bancarios - Manglar'!$M:$M,"")-SUMIFS('Extractos bancarios - Manglar'!$C:$C,'Extractos bancarios - Manglar'!$G:$G,$B9,'Extractos bancarios - Manglar'!$L:$L,H$3,'Extractos bancarios - Manglar'!$M:$M,"",'Extractos bancarios - Manglar'!$K:$K,"Si")*0.19/1.19 -> -18050 | I9: =-SUMIFS(CxP!$K$6:$K$163,CxP!$X$6:$X$163,$B9,CxP!$Y$6:$Y$163,"Si",CxP!$B$6:$B$163,">="&DATE(2026,I$3,1),CxP!$B$6:$B$163,"<="&EOMONTH(DATE(2026,I$3,1),0))-SUMIFS(CxP!$M$6:$M$163,CxP!$X$6:$X$163,$B9,CxP!$Y$6:$Y$163,"Si",CxP!$B$6:$B$163,">="&DATE(2026,I$3,1),CxP!$B$6:$B$163,"<="&EOMONTH(DATE(2026,I$3,1),0))+SUMIFS('Extractos bancarios - Manglar'!$C:$C,'Extractos bancarios - Manglar'!$G:$G,$B9,'Extractos bancarios - Manglar'!$L:$L,I$3,'Extractos bancarios - Manglar'!$M:$M,"")-SUMIFS('Extractos bancarios - Manglar'!$C:$C,'Extractos bancarios - Manglar'!$G:$G,$B9,'Extractos bancarios - Manglar'!$L:$L,I$3,'Extractos bancarios - Manglar'!$M:$M,"",'Extractos bancarios - Manglar'!$K:$K,"Si")*0.19/1.19 -> -18050 | J9: =-SUMIFS(CxP!$K$6:$K$163,CxP!$X$6:$X$163,$B9,CxP!$Y$6:$Y$163,"Si",CxP!$B$6:$B$163,">="&DATE(2026,J$3,1),CxP!$B$6:$B$163,"<="&EOMONTH(DATE(2026,J$3,1),0))-SUMIFS(CxP!$M$6:$M$163,CxP!$X$6:$X$163,$B9,CxP!$Y$6:$Y$163,"Si",CxP!$B$6:$B$163,">="&DATE(2026,J$3,1),CxP!$B$6:$B$163,"<="&EOMONTH(DATE(2026,J$3,1),0))+SUMIFS('Extractos bancarios - Manglar'!$C:$C,'Extractos bancarios - Manglar'!$G:$G,$B9,'Extractos bancarios - Manglar'!$L:$L,J$3,'Extractos bancarios - Manglar'!$M:$M,"")-SUMIFS('Extractos bancarios - Manglar'!$C:$C,'Extractos bancarios - Manglar'!$G:$G,$B9,'Extractos bancarios - Manglar'!$L:$L,J$3,'Extractos bancarios - Manglar'!$M:$M,"",'Extractos bancarios - Manglar'!$K:$K,"Si")*0.19/1.19 -> -18050 | ... N9: =-SUMIFS(CxP!$K$6:$K$163,CxP!$X$6:$X$163,$B9,CxP!$Y$6:$Y$163,"Si",CxP!$B$6:$B$163,">="&DATE(2026,N$3,1),CxP!$B$6:$B$163,"<="&EOMONTH(DATE(2026,N$3,1),0))-SUMIFS(CxP!$M$6:$M$163,CxP!$X$6:$X$163,$B9,CxP!$Y$6:$Y$163,"Si",CxP!$B$6:$B$163,">="&DATE(2026,N$3,1),CxP!$B$6:$B$163,"<="&EOMONTH(DATE(2026,N$3,1),0))+SUMIFS('Extractos bancarios - Manglar'!$C:$C,'Extractos bancarios - Manglar'!$G:$G,$B9,'Extractos bancarios - Manglar'!$L:$L,N$3,'Extractos bancarios - Manglar'!$M:$M,"")-SUMIFS('Extractos bancarios - Manglar'!$C:$C,'Extractos bancarios - Manglar'!$G:$G,$B9,'Extractos bancarios - Manglar'!$L:$L,N$3,'Extractos bancarios - Manglar'!$M:$M,"",'Extractos bancarios - Manglar'!$K:$K,"Si")*0.19/1.19 -> 0 | O9: =+SUM(C9:N9) -> -144400
B10: Costos Operacionales | C10: =-SUMIFS(CxP!$K$6:$K$163,CxP!$X$6:$X$163,$B10,CxP!$Y$6:$Y$163,"Si",CxP!$B$6:$B$163,">="&DATE(2026,C$3,1),CxP!$B$6:$B$163,"<="&EOMONTH(DATE(2026,C$3,1),0))-SUMIFS(CxP!$M$6:$M$163,CxP!$X$6:$X$163,$B10,CxP!$Y$6:$Y$163,"Si",CxP!$B$6:$B$163,">="&DATE(2026,C$3,1),CxP!$B$6:$B$163,"<="&EOMONTH(DATE(2026,C$3,1),0))+SUMIFS('Extractos bancarios - Manglar'!$C:$C,'Extractos bancarios - Manglar'!$G:$G,$B10,'Extractos bancarios - Manglar'!$L:$L,C$3,'Extractos bancarios - Manglar'!$M:$M,"")-SUMIFS('Extractos bancarios - Manglar'!$C:$C,'Extractos bancarios - Manglar'!$G:$G,$B10,'Extractos bancarios - Manglar'!$L:$L,C$3,'Extractos bancarios - Manglar'!$M:$M,"",'Extractos bancarios - Manglar'!$K:$K,"Si")*0.19/1.19 -> 0 | D10: =-SUMIFS(CxP!$K$6:$K$163,CxP!$X$6:$X$163,$B10,CxP!$Y$6:$Y$163,"Si",CxP!$B$6:$B$163,">="&DATE(2026,D$3,1),CxP!$B$6:$B$163,"<="&EOMONTH(DATE(2026,D$3,1),0))-SUMIFS(CxP!$M$6:$M$163,CxP!$X$6:$X$163,$B10,CxP!$Y$6:$Y$163,"Si",CxP!$B$6:$B$163,">="&DATE(2026,D$3,1),CxP!$B$6:$B$163,"<="&EOMONTH(DATE(2026,D$3,1),0))+SUMIFS('Extractos bancarios - Manglar'!$C:$C,'Extractos bancarios - Manglar'!$G:$G,$B10,'Extractos bancarios - Manglar'!$L:$L,D$3,'Extractos bancarios - Manglar'!$M:$M,"")-SUMIFS('Extractos bancarios - Manglar'!$C:$C,'Extractos bancarios - Manglar'!$G:$G,$B10,'Extractos bancarios - Manglar'!$L:$L,D$3,'Extractos bancarios - Manglar'!$M:$M,"",'Extractos bancarios - Manglar'!$K:$K,"Si")*0.19/1.19 -> 0 | E10: =-SUMIFS(CxP!$K$6:$K$163,CxP!$X$6:$X$163,$B10,CxP!$Y$6:$Y$163,"Si",CxP!$B$6:$B$163,">="&DATE(2026,E$3,1),CxP!$B$6:$B$163,"<="&EOMONTH(DATE(2026,E$3,1),0))-SUMIFS(CxP!$M$6:$M$163,CxP!$X$6:$X$163,$B10,CxP!$Y$6:$Y$163,"Si",CxP!$B$6:$B$163,">="&DATE(2026,E$3,1),CxP!$B$6:$B$163,"<="&EOMONTH(DATE(2026,E$3,1),0))+SUMIFS('Extractos bancarios - Manglar'!$C:$C,'Extractos bancarios - Manglar'!$G:$G,$B10,'Extractos bancarios - Manglar'!$L:$L,E$3,'Extractos bancarios - Manglar'!$M:$M,"")-SUMIFS('Extractos bancarios - Manglar'!$C:$C,'Extractos bancarios - Manglar'!$G:$G,$B10,'Extractos bancarios - Manglar'!$L:$L,E$3,'Extractos bancarios - Manglar'!$M:$M,"",'Extractos bancarios - Manglar'!$K:$K,"Si")*0.19/1.19 -> -667854 | F10: =-SUMIFS(CxP!$K$6:$K$163,CxP!$X$6:$X$163,$B10,CxP!$Y$6:$Y$163,"Si",CxP!$B$6:$B$163,">="&DATE(2026,F$3,1),CxP!$B$6:$B$163,"<="&EOMONTH(DATE(2026,F$3,1),0))-SUMIFS(CxP!$M$6:$M$163,CxP!$X$6:$X$163,$B10,CxP!$Y$6:$Y$163,"Si",CxP!$B$6:$B$163,">="&DATE(2026,F$3,1),CxP!$B$6:$B$163,"<="&EOMONTH(DATE(2026,F$3,1),0))+SUMIFS('Extractos bancarios - Manglar'!$C:$C,'Extractos bancarios - Manglar'!$G:$G,$B10,'Extractos bancarios - Manglar'!$L:$L,F$3,'Extractos bancarios - Manglar'!$M:$M,"")-SUMIFS('Extractos bancarios - Manglar'!$C:$C,'Extractos bancarios - Manglar'!$G:$G,$B10,'Extractos bancarios - Manglar'!$L:$L,F$3,'Extractos bancarios - Manglar'!$M:$M,"",'Extractos bancarios - Manglar'!$K:$K,"Si")*0.19/1.19 -> -222529 | G10: =-SUMIFS(CxP!$K$6:$K$163,CxP!$X$6:$X$163,$B10,CxP!$Y$6:$Y$163,"Si",CxP!$B$6:$B$163,">="&DATE(2026,G$3,1),CxP!$B$6:$B$163,"<="&EOMONTH(DATE(2026,G$3,1),0))-SUMIFS(CxP!$M$6:$M$163,CxP!$X$6:$X$163,$B10,CxP!$Y$6:$Y$163,"Si",CxP!$B$6:$B$163,">="&DATE(2026,G$3,1),CxP!$B$6:$B$163,"<="&EOMONTH(DATE(2026,G$3,1),0))+SUMIFS('Extractos bancarios - Manglar'!$C:$C,'Extractos bancarios - Manglar'!$G:$G,$B10,'Extractos bancarios - Manglar'!$L:$L,G$3,'Extractos bancarios - Manglar'!$M:$M,"")-SUMIFS('Extractos bancarios - Manglar'!$C:$C,'Extractos bancarios - Manglar'!$G:$G,$B10,'Extractos bancarios - Manglar'!$L:$L,G$3,'Extractos bancarios - Manglar'!$M:$M,"",'Extractos bancarios - Manglar'!$K:$K,"Si")*0.19/1.19 -> -339061 | H10: =-SUMIFS(CxP!$K$6:$K$163,CxP!$X$6:$X$163,$B10,CxP!$Y$6:$Y$163,"Si",CxP!$B$6:$B$163,">="&DATE(2026,H$3,1),CxP!$B$6:$B$163,"<="&EOMONTH(DATE(2026,H$3,1),0))-SUMIFS(CxP!$M$6:$M$163,CxP!$X$6:$X$163,$B10,CxP!$Y$6:$Y$163,"Si",CxP!$B$6:$B$163,">="&DATE(2026,H$3,1),CxP!$B$6:$B$163,"<="&EOMONTH(DATE(2026,H$3,1),0))+SUMIFS('Extractos bancarios - Manglar'!$C:$C,'Extractos bancarios - Manglar'!$G:$G,$B10,'Extractos bancarios - Manglar'!$L:$L,H$3,'Extractos bancarios - Manglar'!$M:$M,"")-SUMIFS('Extractos bancarios - Manglar'!$C:$C,'Extractos bancarios - Manglar'!$G:$G,$B10,'Extractos bancarios - Manglar'!$L:$L,H$3,'Extractos bancarios - Manglar'!$M:$M,"",'Extractos bancarios - Manglar'!$K:$K,"Si")*0.19/1.19 -> -1134601 | I10: =-SUMIFS(CxP!$K$6:$K$163,CxP!$X$6:$X$163,$B10,CxP!$Y$6:$Y$163,"Si",CxP!$B$6:$B$163,">="&DATE(2026,I$3,1),CxP!$B$6:$B$163,"<="&EOMONTH(DATE(2026,I$3,1),0))-SUMIFS(CxP!$M$6:$M$163,CxP!$X$6:$X$163,$B10,CxP!$Y$6:$Y$163,"Si",CxP!$B$6:$B$163,">="&DATE(2026,I$3,1),CxP!$B$6:$B$163,"<="&EOMONTH(DATE(2026,I$3,1),0))+SUMIFS('Extractos bancarios - Manglar'!$C:$C,'Extractos bancarios - Manglar'!$G:$G,$B10,'Extractos bancarios - Manglar'!$L:$L,I$3,'Extractos bancarios - Manglar'!$M:$M,"")-SUMIFS('Extractos bancarios - Manglar'!$C:$C,'Extractos bancarios - Manglar'!$G:$G,$B10,'Extractos bancarios - Manglar'!$L:$L,I$3,'Extractos bancarios - Manglar'!$M:$M,"",'Extractos bancarios - Manglar'!$K:$K,"Si")*0.19/1.19 -> -11200397 | J10: =-SUMIFS(CxP!$K$6:$K$163,CxP!$X$6:$X$163,$B10,CxP!$Y$6:$Y$163,"Si",CxP!$B$6:$B$163,">="&DATE(2026,J$3,1),CxP!$B$6:$B$163,"<="&EOMONTH(DATE(2026,J$3,1),0))-SUMIFS(CxP!$M$6:$M$163,CxP!$X$6:$X$163,$B10,CxP!$Y$6:$Y$163,"Si",CxP!$B$6:$B$163,">="&DATE(2026,J$3,1),CxP!$B$6:$B$163,"<="&EOMONTH(DATE(2026,J$3,1),0))+SUMIFS('Extractos bancarios - Manglar'!$C:$C,'Extractos bancarios - Manglar'!$G:$G,$B10,'Extractos bancarios - Manglar'!$L:$L,J$3,'Extractos bancarios - Manglar'!$M:$M,"")-SUMIFS('Extractos bancarios - Manglar'!$C:$C,'Extractos bancarios - Manglar'!$G:$G,$B10,'Extractos bancarios - Manglar'!$L:$L,J$3,'Extractos bancarios - Manglar'!$M:$M,"",'Extractos bancarios - Manglar'!$K:$K,"Si")*0.19/1.19 -> -531388.67 | ... N10: =-SUMIFS(CxP!$K$6:$K$163,CxP!$X$6:$X$163,$B10,CxP!$Y$6:$Y$163,"Si",CxP!$B$6:$B$163,">="&DATE(2026,N$3,1),CxP!$B$6:$B$163,"<="&EOMONTH(DATE(2026,N$3,1),0))-SUMIFS(CxP!$M$6:$M$163,CxP!$X$6:$X$163,$B10,CxP!$Y$6:$Y$163,"Si",CxP!$B$6:$B$163,">="&DATE(2026,N$3,1),CxP!$B$6:$B$163,"<="&EOMONTH(DATE(2026,N$3,1),0))+SUMIFS('Extractos bancarios - Manglar'!$C:$C,'Extractos bancarios - Manglar'!$G:$G,$B10,'Extractos bancarios - Manglar'!$L:$L,N$3,'Extractos bancarios - Manglar'!$M:$M,"")-SUMIFS('Extractos bancarios - Manglar'!$C:$C,'Extractos bancarios - Manglar'!$G:$G,$B10,'Extractos bancarios - Manglar'!$L:$L,N$3,'Extractos bancarios - Manglar'!$M:$M,"",'Extractos bancarios - Manglar'!$K:$K,"Si")*0.19/1.19 -> 0 | O10: =+SUM(C10:N10) -> -28173402
B11: Gastos Variables | C11: =-SUMIFS(CxP!$K$6:$K$163,CxP!$X$6:$X$163,$B11,CxP!$Y$6:$Y$163,"Si",CxP!$B$6:$B$163,">="&DATE(2026,C$3,1),CxP!$B$6:$B$163,"<="&EOMONTH(DATE(2026,C$3,1),0))-SUMIFS(CxP!$M$6:$M$163,CxP!$X$6:$X$163,$B11,CxP!$Y$6:$Y$163,"Si",CxP!$B$6:$B$163,">="&DATE(2026,C$3,1),CxP!$B$6:$B$163,"<="&EOMONTH(DATE(2026,C$3,1),0))+SUMIFS('Extractos bancarios - Manglar'!$C:$C,'Extractos bancarios - Manglar'!$G:$G,$B11,'Extractos bancarios - Manglar'!$L:$L,C$3,'Extractos bancarios - Manglar'!$M:$M,"")-SUMIFS('Extractos bancarios - Manglar'!$C:$C,'Extractos bancarios - Manglar'!$G:$G,$B11,'Extractos bancarios - Manglar'!$L:$L,C$3,'Extractos bancarios - Manglar'!$M:$M,"",'Extractos bancarios - Manglar'!$K:$K,"Si")*0.19/1.19 -> 0 | D11: =-SUMIFS(CxP!$K$6:$K$163,CxP!$X$6:$X$163,$B11,CxP!$Y$6:$Y$163,"Si",CxP!$B$6:$B$163,">="&DATE(2026,D$3,1),CxP!$B$6:$B$163,"<="&EOMONTH(DATE(2026,D$3,1),0))-SUMIFS(CxP!$M$6:$M$163,CxP!$X$6:$X$163,$B11,CxP!$Y$6:$Y$163,"Si",CxP!$B$6:$B$163,">="&DATE(2026,D$3,1),CxP!$B$6:$B$163,"<="&EOMONTH(DATE(2026,D$3,1),0))+SUMIFS('Extractos bancarios - Manglar'!$C:$C,'Extractos bancarios - Manglar'!$G:$G,$B11,'Extractos bancarios - Manglar'!$L:$L,D$3,'Extractos bancarios - Manglar'!$M:$M,"")-SUMIFS('Extractos bancarios - Manglar'!$C:$C,'Extractos bancarios - Manglar'!$G:$G,$B11,'Extractos bancarios - Manglar'!$L:$L,D$3,'Extractos bancarios - Manglar'!$M:$M,"",'Extractos bancarios - Manglar'!$K:$K,"Si")*0.19/1.19 -> 0 | E11: =-SUMIFS(CxP!$K$6:$K$163,CxP!$X$6:$X$163,$B11,CxP!$Y$6:$Y$163,"Si",CxP!$B$6:$B$163,">="&DATE(2026,E$3,1),CxP!$B$6:$B$163,"<="&EOMONTH(DATE(2026,E$3,1),0))-SUMIFS(CxP!$M$6:$M$163,CxP!$X$6:$X$163,$B11,CxP!$Y$6:$Y$163,"Si",CxP!$B$6:$B$163,">="&DATE(2026,E$3,1),CxP!$B$6:$B$163,"<="&EOMONTH(DATE(2026,E$3,1),0))+SUMIFS('Extractos bancarios - Manglar'!$C:$C,'Extractos bancarios - Manglar'!$G:$G,$B11,'Extractos bancarios - Manglar'!$L:$L,E$3,'Extractos bancarios - Manglar'!$M:$M,"")-SUMIFS('Extractos bancarios - Manglar'!$C:$C,'Extractos bancarios - Manglar'!$G:$G,$B11,'Extractos bancarios - Manglar'!$L:$L,E$3,'Extractos bancarios - Manglar'!$M:$M,"",'Extractos bancarios - Manglar'!$K:$K,"Si")*0.19/1.19 -> -7519.77 | F11: =-SUMIFS(CxP!$K$6:$K$163,CxP!$X$6:$X$163,$B11,CxP!$Y$6:$Y$163,"Si",CxP!$B$6:$B$163,">="&DATE(2026,F$3,1),CxP!$B$6:$B$163,"<="&EOMONTH(DATE(2026,F$3,1),0))-SUMIFS(CxP!$M$6:$M$163,CxP!$X$6:$X$163,$B11,CxP!$Y$6:$Y$163,"Si",CxP!$B$6:$B$163,">="&DATE(2026,F$3,1),CxP!$B$6:$B$163,"<="&EOMONTH(DATE(2026,F$3,1),0))+SUMIFS('Extractos bancarios - Manglar'!$C:$C,'Extractos bancarios - Manglar'!$G:$G,$B11,'Extractos bancarios - Manglar'!$L:$L,F$3,'Extractos bancarios - Manglar'!$M:$M,"")-SUMIFS('Extractos bancarios - Manglar'!$C:$C,'Extractos bancarios - Manglar'!$G:$G,$B11,'Extractos bancarios - Manglar'!$L:$L,F$3,'Extractos bancarios - Manglar'!$M:$M,"",'Extractos bancarios - Manglar'!$K:$K,"Si")*0.19/1.19 -> 8199.78 | G11: =-SUMIFS(CxP!$K$6:$K$163,CxP!$X$6:$X$163,$B11,CxP!$Y$6:$Y$163,"Si",CxP!$B$6:$B$163,">="&DATE(2026,G$3,1),CxP!$B$6:$B$163,"<="&EOMONTH(DATE(2026,G$3,1),0))-SUMIFS(CxP!$M$6:$M$163,CxP!$X$6:$X$163,$B11,CxP!$Y$6:$Y$163,"Si",CxP!$B$6:$B$163,">="&DATE(2026,G$3,1),CxP!$B$6:$B$163,"<="&EOMONTH(DATE(2026,G$3,1),0))+SUMIFS('Extractos bancarios - Manglar'!$C:$C,'Extractos bancarios - Manglar'!$G:$G,$B11,'Extractos bancarios - Manglar'!$L:$L,G$3,'Extractos bancarios - Manglar'!$M:$M,"")-SUMIFS('Extractos bancarios - Manglar'!$C:$C,'Extractos bancarios - Manglar'!$G:$G,$B11,'Extractos bancarios - Manglar'!$L:$L,G$3,'Extractos bancarios - Manglar'!$M:$M,"",'Extractos bancarios - Manglar'!$K:$K,"Si")*0.19/1.19 -> -114199 | H11: =-SUMIFS(CxP!$K$6:$K$163,CxP!$X$6:$X$163,$B11,CxP!$Y$6:$Y$163,"Si",CxP!$B$6:$B$163,">="&DATE(2026,H$3,1),CxP!$B$6:$B$163,"<="&EOMONTH(DATE(2026,H$3,1),0))-SUMIFS(CxP!$M$6:$M$163,CxP!$X$6:$X$163,$B11,CxP!$Y$6:$Y$163,"Si",CxP!$B$6:$B$163,">="&DATE(2026,H$3,1),CxP!$B$6:$B$163,"<="&EOMONTH(DATE(2026,H$3,1),0))+SUMIFS('Extractos bancarios - Manglar'!$C:$C,'Extractos bancarios - Manglar'!$G:$G,$B11,'Extractos bancarios - Manglar'!$L:$L,H$3,'Extractos bancarios - Manglar'!$M:$M,"")-SUMIFS('Extractos bancarios - Manglar'!$C:$C,'Extractos bancarios - Manglar'!$G:$G,$B11,'Extractos bancarios - Manglar'!$L:$L,H$3,'Extractos bancarios - Manglar'!$M:$M,"",'Extractos bancarios - Manglar'!$K:$K,"Si")*0.19/1.19 -> -382139.66 | I11: =-SUMIFS(CxP!$K$6:$K$163,CxP!$X$6:$X$163,$B11,CxP!$Y$6:$Y$163,"Si",CxP!$B$6:$B$163,">="&DATE(2026,I$3,1),CxP!$B$6:$B$163,"<="&EOMONTH(DATE(2026,I$3,1),0))-SUMIFS(CxP!$M$6:$M$163,CxP!$X$6:$X$163,$B11,CxP!$Y$6:$Y$163,"Si",CxP!$B$6:$B$163,">="&DATE(2026,I$3,1),CxP!$B$6:$B$163,"<="&EOMONTH(DATE(2026,I$3,1),0))+SUMIFS('Extractos bancarios - Manglar'!$C:$C,'Extractos bancarios - Manglar'!$G:$G,$B11,'Extractos bancarios - Manglar'!$L:$L,I$3,'Extractos bancarios - Manglar'!$M:$M,"")-SUMIFS('Extractos bancarios - Manglar'!$C:$C,'Extractos bancarios - Manglar'!$G:$G,$B11,'Extractos bancarios - Manglar'!$L:$L,I$3,'Extractos bancarios - Manglar'!$M:$M,"",'Extractos bancarios - Manglar'!$K:$K,"Si")*0.19/1.19 -> -386753.79 | J11: =-SUMIFS(CxP!$K$6:$K$163,CxP!$X$6:$X$163,$B11,CxP!$Y$6:$Y$163,"Si",CxP!$B$6:$B$163,">="&DATE(2026,J$3,1),CxP!$B$6:$B$163,"<="&EOMONTH(DATE(2026,J$3,1),0))-SUMIFS(CxP!$M$6:$M$163,CxP!$X$6:$X$163,$B11,CxP!$Y$6:$Y$163,"Si",CxP!$B$6:$B$163,">="&DATE(2026,J$3,1),CxP!$B$6:$B$163,"<="&EOMONTH(DATE(2026,J$3,1),0))+SUMIFS('Extractos bancarios - Manglar'!$C:$C,'Extractos bancarios - Manglar'!$G:$G,$B11,'Extractos bancarios - Manglar'!$L:$L,J$3,'Extractos bancarios - Manglar'!$M:$M,"")-SUMIFS('Extractos bancarios - Manglar'!$C:$C,'Extractos bancarios - Manglar'!$G:$G,$B11,'Extractos bancarios - Manglar'!$L:$L,J$3,'Extractos bancarios - Manglar'!$M:$M,"",'Extractos bancarios - Manglar'!$K:$K,"Si")*0.19/1.19 -> -159676.11 | ... N11: =-SUMIFS(CxP!$K$6:$K$163,CxP!$X$6:$X$163,$B11,CxP!$Y$6:$Y$163,"Si",CxP!$B$6:$B$163,">="&DATE(2026,N$3,1),CxP!$B$6:$B$163,"<="&EOMONTH(DATE(2026,N$3,1),0))-SUMIFS(CxP!$M$6:$M$163,CxP!$X$6:$X$163,$B11,CxP!$Y$6:$Y$163,"Si",CxP!$B$6:$B$163,">="&DATE(2026,N$3,1),CxP!$B$6:$B$163,"<="&EOMONTH(DATE(2026,N$3,1),0))+SUMIFS('Extractos bancarios - Manglar'!$C:$C,'Extractos bancarios - Manglar'!$G:$G,$B11,'Extractos bancarios - Manglar'!$L:$L,N$3,'Extractos bancarios - Manglar'!$M:$M,"")-SUMIFS('Extractos bancarios - Manglar'!$C:$C,'Extractos bancarios - Manglar'!$G:$G,$B11,'Extractos bancarios - Manglar'!$L:$L,N$3,'Extractos bancarios - Manglar'!$M:$M,"",'Extractos bancarios - Manglar'!$K:$K,"Si")*0.19/1.19 -> 0 | O11: =+SUM(C11:N11) -> -1666908.3
B12: Otros Gastos | C12: =SUMIFS('Extractos bancarios - Manglar'!$C:$C,'Extractos bancarios - Manglar'!$G:$G,$B12,'Extractos bancarios - Manglar'!$L:$L,C$3) -> 0 | D12: =SUMIFS('Extractos bancarios - Manglar'!$C:$C,'Extractos bancarios - Manglar'!$G:$G,$B12,'Extractos bancarios - Manglar'!$L:$L,D$3) -> 0 | E12: =SUMIFS('Extractos bancarios - Manglar'!$C:$C,'Extractos bancarios - Manglar'!$G:$G,$B12,'Extractos bancarios - Manglar'!$L:$L,E$3) -> 0 | F12: =SUMIFS('Extractos bancarios - Manglar'!$C:$C,'Extractos bancarios - Manglar'!$G:$G,$B12,'Extractos bancarios - Manglar'!$L:$L,F$3) -> 0 | G12: =SUMIFS('Extractos bancarios - Manglar'!$C:$C,'Extractos bancarios - Manglar'!$G:$G,$B12,'Extractos bancarios - Manglar'!$L:$L,G$3) -> 0 | H12: =SUMIFS('Extractos bancarios - Manglar'!$C:$C,'Extractos bancarios - Manglar'!$G:$G,$B12,'Extractos bancarios - Manglar'!$L:$L,H$3) -> 0 | I12: =SUMIFS('Extractos bancarios - Manglar'!$C:$C,'Extractos bancarios - Manglar'!$G:$G,$B12,'Extractos bancarios - Manglar'!$L:$L,I$3) -> 0 | J12: =SUMIFS('Extractos bancarios - Manglar'!$C:$C,'Extractos bancarios - Manglar'!$G:$G,$B12,'Extractos bancarios - Manglar'!$L:$L,J$3) -> 0 | ... N12: =SUMIFS('Extractos bancarios - Manglar'!$C:$C,'Extractos bancarios - Manglar'!$G:$G,$B12,'Extractos bancarios - Manglar'!$L:$L,N$3) -> 0 | O12: =+SUM(C12:N12) -> 0
B13: Resultado Final | C13: =C6+SUM(C8:C12) -> 0 | D13: =D6+SUM(D8:D12) -> 0 | E13: =E6+SUM(E8:E12) -> -789523.77 | F13: =F6+SUM(F8:F12) -> 27930296 | G13: =G6+SUM(G8:G12) -> 2.441468e+08 | H13: =H6+SUM(H8:H12) -> -1.6676622e+08 | I13: =I6+SUM(I8:I12) -> -8657065.1 | J13: =J6+SUM(J8:J12) -> 43231220 | ... N13: =N6+SUM(N8:N12) -> 0 | O13: =+SUM(C13:N13) -> 99843742
B14: Margen % | C14: =IFERROR(+C13/C$4,"-") -> - | D14: =IFERROR(+D13/D$4,"-") -> - | E14: =IFERROR(+E13/E$4,"-") -> - | F14: =IFERROR(+F13/F$4,"-") -> 0.69877145 | G14: =IFERROR(+G13/G$4,"-") -> 0.94836986 | H14: =IFERROR(+H13/H$4,"-") -> - | I14: =IFERROR(+I13/I$4,"-") -> -0.20310351 | J14: =IFERROR(+J13/J$4,"-") -> 0.68944281 | ... O14: =IFERROR(+O13/O$4,"-") -> 0.2051521
B16: Flujo de Caja
B17: Saldo Inicial | C17: 0 | D17: =C27 -> 0 | E17: =D27 -> 0 | F17: =E27 -> 3628284.1 | G17: =F27 -> 46685528 | H17: =G27 -> 2.514566e+08 | I17: =H27 -> 1.9504544e+08 | J17: =I27 -> 1.0426245e+08 | K17: =J27 -> 75999625 | ... N17: =M27 -> 63360593
B18: Ingresos | C18: =SUMIFS('Extractos bancarios - Manglar'!$C:$C,'Extractos bancarios - Manglar'!$G:$G,$B18,'Extractos bancarios - Manglar'!$F:$F,C$3) -> 0 | D18: =SUMIFS('Extractos bancarios - Manglar'!$C:$C,'Extractos bancarios - Manglar'!$G:$G,$B18,'Extractos bancarios - Manglar'!$F:$F,D$3) -> 0 | E18: =SUMIFS('Extractos bancarios - Manglar'!$C:$C,'Extractos bancarios - Manglar'!$G:$G,$B18,'Extractos bancarios - Manglar'!$F:$F,E$3) -> 0 | F18: =SUMIFS('Extractos bancarios - Manglar'!$C:$C,'Extractos bancarios - Manglar'!$G:$G,$B18,'Extractos bancarios - Manglar'!$F:$F,F$3) -> 46656750 | G18: =SUMIFS('Extractos bancarios - Manglar'!$C:$C,'Extractos bancarios - Manglar'!$G:$G,$B18,'Extractos bancarios - Manglar'!$F:$F,G$3) -> 247410429 | H18: =SUMIFS('Extractos bancarios - Manglar'!$C:$C,'Extractos bancarios - Manglar'!$G:$G,$B18,'Extractos bancarios - Manglar'!$F:$F,H$3) -> 47109266 | I18: =SUMIFS('Extractos bancarios - Manglar'!$C:$C,'Extractos bancarios - Manglar'!$G:$G,$B18,'Extractos bancarios - Manglar'!$F:$F,I$3) -> 20102227 | J18: =SUMIFS('Extractos bancarios - Manglar'!$C:$C,'Extractos bancarios - Manglar'!$G:$G,$B18,'Extractos bancarios - Manglar'!$F:$F,J$3) -> 28009175 | ... N18: =SUMIFS('Extractos bancarios - Manglar'!$C:$C,'Extractos bancarios - Manglar'!$G:$G,$B18,'Extractos bancarios - Manglar'!$F:$F,N$3) -> 0
B19: Otros Ingresos | C19: =SUMIFS('Extractos bancarios - Manglar'!$C:$C,'Extractos bancarios - Manglar'!$G:$G,$B19,'Extractos bancarios - Manglar'!$F:$F,C$3) -> 0 | D19: =SUMIFS('Extractos bancarios - Manglar'!$C:$C,'Extractos bancarios - Manglar'!$G:$G,$B19,'Extractos bancarios - Manglar'!$F:$F,D$3) -> 0 | E19: =SUMIFS('Extractos bancarios - Manglar'!$C:$C,'Extractos bancarios - Manglar'!$G:$G,$B19,'Extractos bancarios - Manglar'!$F:$F,E$3) -> 4500000 | F19: =SUMIFS('Extractos bancarios - Manglar'!$C:$C,'Extractos bancarios - Manglar'!$G:$G,$B19,'Extractos bancarios - Manglar'!$F:$F,F$3) -> 6500000 | G19: =SUMIFS('Extractos bancarios - Manglar'!$C:$C,'Extractos bancarios - Manglar'!$G:$G,$B19,'Extractos bancarios - Manglar'!$F:$F,G$3) -> 0 | H19: =SUMIFS('Extractos bancarios - Manglar'!$C:$C,'Extractos bancarios - Manglar'!$G:$G,$B19,'Extractos bancarios - Manglar'!$F:$F,H$3) -> 0 | I19: =SUMIFS('Extractos bancarios - Manglar'!$C:$C,'Extractos bancarios - Manglar'!$G:$G,$B19,'Extractos bancarios - Manglar'!$F:$F,I$3) -> 0 | J19: =SUMIFS('Extractos bancarios - Manglar'!$C:$C,'Extractos bancarios - Manglar'!$G:$G,$B19,'Extractos bancarios - Manglar'!$F:$F,J$3) -> 0 | ... N19: =SUMIFS('Extractos bancarios - Manglar'!$C:$C,'Extractos bancarios - Manglar'!$G:$G,$B19,'Extractos bancarios - Manglar'!$F:$F,N$3) -> 0
B20: Costo Ventas | C20: =SUMIFS('Extractos bancarios - Manglar'!$C:$C,'Extractos bancarios - Manglar'!$G:$G,$B20,'Extractos bancarios - Manglar'!$F:$F,C$3) -> 0 | D20: =SUMIFS('Extractos bancarios - Manglar'!$C:$C,'Extractos bancarios - Manglar'!$G:$G,$B20,'Extractos bancarios - Manglar'!$F:$F,D$3) -> 0 | E20: =SUMIFS('Extractos bancarios - Manglar'!$C:$C,'Extractos bancarios - Manglar'!$G:$G,$B20,'Extractos bancarios - Manglar'!$F:$F,E$3) -> 0 | F20: =SUMIFS('Extractos bancarios - Manglar'!$C:$C,'Extractos bancarios - Manglar'!$G:$G,$B20,'Extractos bancarios - Manglar'!$F:$F,F$3) -> -9862800 | G20: =SUMIFS('Extractos bancarios - Manglar'!$C:$C,'Extractos bancarios - Manglar'!$G:$G,$B20,'Extractos bancarios - Manglar'!$F:$F,G$3) -> -35504330 | H20: =SUMIFS('Extractos bancarios - Manglar'!$C:$C,'Extractos bancarios - Manglar'!$G:$G,$B20,'Extractos bancarios - Manglar'!$F:$F,H$3) -> -98158229 | I20: =SUMIFS('Extractos bancarios - Manglar'!$C:$C,'Extractos bancarios - Manglar'!$G:$G,$B20,'Extractos bancarios - Manglar'!$F:$F,I$3) -> -90085008 | J20: =SUMIFS('Extractos bancarios - Manglar'!$C:$C,'Extractos bancarios - Manglar'!$G:$G,$B20,'Extractos bancarios - Manglar'!$F:$F,J$3) -> -36896839 | ... N20: =SUMIFS('Extractos bancarios - Manglar'!$C:$C,'Extractos bancarios - Manglar'!$G:$G,$B20,'Extractos bancarios - Manglar'!$F:$F,N$3) -> 0
B21: Costos Fijos | C21: =SUMIFS('Extractos bancarios - Manglar'!$C:$C,'Extractos bancarios - Manglar'!$G:$G,$B21,'Extractos bancarios - Manglar'!$F:$F,C$3) -> 0 | D21: =SUMIFS('Extractos bancarios - Manglar'!$C:$C,'Extractos bancarios - Manglar'!$G:$G,$B21,'Extractos bancarios - Manglar'!$F:$F,D$3) -> 0 | E21: =SUMIFS('Extractos bancarios - Manglar'!$C:$C,'Extractos bancarios - Manglar'!$G:$G,$B21,'Extractos bancarios - Manglar'!$F:$F,E$3) -> -18050 | F21: =SUMIFS('Extractos bancarios - Manglar'!$C:$C,'Extractos bancarios - Manglar'!$G:$G,$B21,'Extractos bancarios - Manglar'!$F:$F,F$3) -> -18050 | G21: =SUMIFS('Extractos bancarios - Manglar'!$C:$C,'Extractos bancarios - Manglar'!$G:$G,$B21,'Extractos bancarios - Manglar'!$F:$F,G$3) -> -18050 | H21: =SUMIFS('Extractos bancarios - Manglar'!$C:$C,'Extractos bancarios - Manglar'!$G:$G,$B21,'Extractos bancarios - Manglar'!$F:$F,H$3) -> -18050 | I21: =SUMIFS('Extractos bancarios - Manglar'!$C:$C,'Extractos bancarios - Manglar'!$G:$G,$B21,'Extractos bancarios - Manglar'!$F:$F,I$3) -> -18050 | J21: =SUMIFS('Extractos bancarios - Manglar'!$C:$C,'Extractos bancarios - Manglar'!$G:$G,$B21,'Extractos bancarios - Manglar'!$F:$F,J$3) -> -18050 | ... N21: =SUMIFS('Extractos bancarios - Manglar'!$C:$C,'Extractos bancarios - Manglar'!$G:$G,$B21,'Extractos bancarios - Manglar'!$F:$F,N$3) -> 0
B22: Costos Operacionales | C22: =SUMIFS('Extractos bancarios - Manglar'!$C:$C,'Extractos bancarios - Manglar'!$G:$G,$B22,'Extractos bancarios - Manglar'!$F:$F,C$3) -> 0 | D22: =SUMIFS('Extractos bancarios - Manglar'!$C:$C,'Extractos bancarios - Manglar'!$G:$G,$B22,'Extractos bancarios - Manglar'!$F:$F,D$3) -> 0 | E22: =SUMIFS('Extractos bancarios - Manglar'!$C:$C,'Extractos bancarios - Manglar'!$G:$G,$B22,'Extractos bancarios - Manglar'!$F:$F,E$3) -> -844704 | F22: =SUMIFS('Extractos bancarios - Manglar'!$C:$C,'Extractos bancarios - Manglar'!$G:$G,$B22,'Extractos bancarios - Manglar'!$F:$F,F$3) -> -222529 | G22: =SUMIFS('Extractos bancarios - Manglar'!$C:$C,'Extractos bancarios - Manglar'!$G:$G,$B22,'Extractos bancarios - Manglar'!$F:$F,G$3) -> -679448 | H22: =SUMIFS('Extractos bancarios - Manglar'!$C:$C,'Extractos bancarios - Manglar'!$G:$G,$B22,'Extractos bancarios - Manglar'!$F:$F,H$3) -> -1136030 | I22: =SUMIFS('Extractos bancarios - Manglar'!$C:$C,'Extractos bancarios - Manglar'!$G:$G,$B22,'Extractos bancarios - Manglar'!$F:$F,I$3) -> -12831543 | J22: =SUMIFS('Extractos bancarios - Manglar'!$C:$C,'Extractos bancarios - Manglar'!$G:$G,$B22,'Extractos bancarios - Manglar'!$F:$F,J$3) -> -788548.33 | ... N22: =SUMIFS('Extractos bancarios - Manglar'!$C:$C,'Extractos bancarios - Manglar'!$G:$G,$B22,'Extractos bancarios - Manglar'!$F:$F,N$3) -> 0
B23: Gastos Variables | C23: =SUMIFS('Extractos bancarios - Manglar'!$C:$C,'Extractos bancarios - Manglar'!$G:$G,$B23,'Extractos bancarios - Manglar'!$F:$F,C$3) -> 0 | D23: =SUMIFS('Extractos bancarios - Manglar'!$C:$C,'Extractos bancarios - Manglar'!$G:$G,$B23,'Extractos bancarios - Manglar'!$F:$F,D$3) -> 0 | E23: =SUMIFS('Extractos bancarios - Manglar'!$C:$C,'Extractos bancarios - Manglar'!$G:$G,$B23,'Extractos bancarios - Manglar'!$F:$F,E$3) -> -7519.77 | F23: =SUMIFS('Extractos bancarios - Manglar'!$C:$C,'Extractos bancarios - Manglar'!$G:$G,$B23,'Extractos bancarios - Manglar'!$F:$F,F$3) -> 8199.78 | G23: =SUMIFS('Extractos bancarios - Manglar'!$C:$C,'Extractos bancarios - Manglar'!$G:$G,$B23,'Extractos bancarios - Manglar'!$F:$F,G$3) -> -114199 | H23: =SUMIFS('Extractos bancarios - Manglar'!$C:$C,'Extractos bancarios - Manglar'!$G:$G,$B23,'Extractos bancarios - Manglar'!$F:$F,H$3) -> -382139.66 | I23: =SUMIFS('Extractos bancarios - Manglar'!$C:$C,'Extractos bancarios - Manglar'!$G:$G,$B23,'Extractos bancarios - Manglar'!$F:$F,I$3) -> -386753.79 | J23: =SUMIFS('Extractos bancarios - Manglar'!$C:$C,'Extractos bancarios - Manglar'!$G:$G,$B23,'Extractos bancarios - Manglar'!$F:$F,J$3) -> -159676.11 | ... N23: =SUMIFS('Extractos bancarios - Manglar'!$C:$C,'Extractos bancarios - Manglar'!$G:$G,$B23,'Extractos bancarios - Manglar'!$F:$F,N$3) -> 0
B24: Otros Gastos | C24: =SUMIFS('Extractos bancarios - Manglar'!$C:$C,'Extractos bancarios - Manglar'!$G:$G,$B24,'Extractos bancarios - Manglar'!$F:$F,C$3) -> 0 | D24: =SUMIFS('Extractos bancarios - Manglar'!$C:$C,'Extractos bancarios - Manglar'!$G:$G,$B24,'Extractos bancarios - Manglar'!$F:$F,D$3) -> 0 | E24: =SUMIFS('Extractos bancarios - Manglar'!$C:$C,'Extractos bancarios - Manglar'!$G:$G,$B24,'Extractos bancarios - Manglar'!$F:$F,E$3) -> 0 | F24: =SUMIFS('Extractos bancarios - Manglar'!$C:$C,'Extractos bancarios - Manglar'!$G:$G,$B24,'Extractos bancarios - Manglar'!$F:$F,F$3) -> 0 | G24: =SUMIFS('Extractos bancarios - Manglar'!$C:$C,'Extractos bancarios - Manglar'!$G:$G,$B24,'Extractos bancarios - Manglar'!$F:$F,G$3) -> -2500000 | H24: =SUMIFS('Extractos bancarios - Manglar'!$C:$C,'Extractos bancarios - Manglar'!$G:$G,$B24,'Extractos bancarios - Manglar'!$F:$F,H$3) -> 0 | I24: =SUMIFS('Extractos bancarios - Manglar'!$C:$C,'Extractos bancarios - Manglar'!$G:$G,$B24,'Extractos bancarios - Manglar'!$F:$F,I$3) -> -7553270 | J24: =SUMIFS('Extractos bancarios - Manglar'!$C:$C,'Extractos bancarios - Manglar'!$G:$G,$B24,'Extractos bancarios - Manglar'!$F:$F,J$3) -> 0 | ... N24: =SUMIFS('Extractos bancarios - Manglar'!$C:$C,'Extractos bancarios - Manglar'!$G:$G,$B24,'Extractos bancarios - Manglar'!$F:$F,N$3) -> 0
B25: (-) Distribución Socios | C25: =SUMIFS('Extractos bancarios - Manglar'!$C:$C,'Extractos bancarios - Manglar'!$G:$G,$B25,'Extractos bancarios - Manglar'!$F:$F,C$3) -> 0 | D25: =SUMIFS('Extractos bancarios - Manglar'!$C:$C,'Extractos bancarios - Manglar'!$G:$G,$B25,'Extractos bancarios - Manglar'!$F:$F,D$3) -> 0 | E25: =SUMIFS('Extractos bancarios - Manglar'!$C:$C,'Extractos bancarios - Manglar'!$G:$G,$B25,'Extractos bancarios - Manglar'!$F:$F,E$3) -> 0 | F25: =SUMIFS('Extractos bancarios - Manglar'!$C:$C,'Extractos bancarios - Manglar'!$G:$G,$B25,'Extractos bancarios - Manglar'!$F:$F,F$3) -> 0 | G25: =SUMIFS('Extractos bancarios - Manglar'!$C:$C,'Extractos bancarios - Manglar'!$G:$G,$B25,'Extractos bancarios - Manglar'!$F:$F,G$3) -> 0 | H25: =SUMIFS('Extractos bancarios - Manglar'!$C:$C,'Extractos bancarios - Manglar'!$G:$G,$B25,'Extractos bancarios - Manglar'!$F:$F,H$3) -> 0 | I25: =SUMIFS('Extractos bancarios - Manglar'!$C:$C,'Extractos bancarios - Manglar'!$G:$G,$B25,'Extractos bancarios - Manglar'!$F:$F,I$3) -> 0 | J25: =SUMIFS('Extractos bancarios - Manglar'!$C:$C,'Extractos bancarios - Manglar'!$G:$G,$B25,'Extractos bancarios - Manglar'!$F:$F,J$3) -> 0 | ... N25: =SUMIFS('Extractos bancarios - Manglar'!$C:$C,'Extractos bancarios - Manglar'!$G:$G,$B25,'Extractos bancarios - Manglar'!$F:$F,N$3) -> 0 | O25: =SUM(C25:N25) -> 0
B26: (-) Impuestos y IVA pagados | C26: =SUMIFS('Extractos bancarios - Manglar'!$C:$C,'Extractos bancarios - Manglar'!$G:$G,"Impuestos",'Extractos bancarios - Manglar'!$F:$F,C$3)+SUMIFS('Extractos bancarios - Manglar'!$C:$C,'Extractos bancarios - Manglar'!$G:$G,"Imp x Pagar - IVA",'Extractos bancarios - Manglar'!$F:$F,C$3) -> 0 | D26: =SUMIFS('Extractos bancarios - Manglar'!$C:$C,'Extractos bancarios - Manglar'!$G:$G,"Impuestos",'Extractos bancarios - Manglar'!$F:$F,D$3)+SUMIFS('Extractos bancarios - Manglar'!$C:$C,'Extractos bancarios - Manglar'!$G:$G,"Imp x Pagar - IVA",'Extractos bancarios - Manglar'!$F:$F,D$3) -> 0 | E26: =SUMIFS('Extractos bancarios - Manglar'!$C:$C,'Extractos bancarios - Manglar'!$G:$G,"Impuestos",'Extractos bancarios - Manglar'!$F:$F,E$3)+SUMIFS('Extractos bancarios - Manglar'!$C:$C,'Extractos bancarios - Manglar'!$G:$G,"Imp x Pagar - IVA",'Extractos bancarios - Manglar'!$F:$F,E$3) -> -1442.1 | F26: =SUMIFS('Extractos bancarios - Manglar'!$C:$C,'Extractos bancarios - Manglar'!$G:$G,"Impuestos",'Extractos bancarios - Manglar'!$F:$F,F$3)+SUMIFS('Extractos bancarios - Manglar'!$C:$C,'Extractos bancarios - Manglar'!$G:$G,"Imp x Pagar - IVA",'Extractos bancarios - Manglar'!$F:$F,F$3) -> -4326.3 | G26: =SUMIFS('Extractos bancarios - Manglar'!$C:$C,'Extractos bancarios - Manglar'!$G:$G,"Impuestos",'Extractos bancarios - Manglar'!$F:$F,G$3)+SUMIFS('Extractos bancarios - Manglar'!$C:$C,'Extractos bancarios - Manglar'!$G:$G,"Imp x Pagar - IVA",'Extractos bancarios - Manglar'!$F:$F,G$3) -> -3823326 | H26: =SUMIFS('Extractos bancarios - Manglar'!$C:$C,'Extractos bancarios - Manglar'!$G:$G,"Impuestos",'Extractos bancarios - Manglar'!$F:$F,H$3)+SUMIFS('Extractos bancarios - Manglar'!$C:$C,'Extractos bancarios - Manglar'!$G:$G,"Imp x Pagar - IVA",'Extractos bancarios - Manglar'!$F:$F,H$3) -> -3825978.3 | I26: =SUMIFS('Extractos bancarios - Manglar'!$C:$C,'Extractos bancarios - Manglar'!$G:$G,"Impuestos",'Extractos bancarios - Manglar'!$F:$F,I$3)+SUMIFS('Extractos bancarios - Manglar'!$C:$C,'Extractos bancarios - Manglar'!$G:$G,"Imp x Pagar - IVA",'Extractos bancarios - Manglar'!$F:$F,I$3) -> -10598.1 | J26: =SUMIFS('Extractos bancarios - Manglar'!$C:$C,'Extractos bancarios - Manglar'!$G:$G,"Impuestos",'Extractos bancarios - Manglar'!$F:$F,J$3)+SUMIFS('Extractos bancarios - Manglar'!$C:$C,'Extractos bancarios - Manglar'!$G:$G,"Imp x Pagar - IVA",'Extractos bancarios - Manglar'!$F:$F,J$3) -> -18408884 | ... N26: =SUMIFS('Extractos bancarios - Manglar'!$C:$C,'Extractos bancarios - Manglar'!$G:$G,"Impuestos",'Extractos bancarios - Manglar'!$F:$F,N$3)+SUMIFS('Extractos bancarios - Manglar'!$C:$C,'Extractos bancarios - Manglar'!$G:$G,"Imp x Pagar - IVA",'Extractos bancarios - Manglar'!$F:$F,N$3) -> 0 | O26: =SUM(C26:N26) -> -44299223
B27: Saldo Final | C27: =C17+C18+C19+SUM(C20:C24)+C25+C26 -> 0 | D27: =D17+D18+D19+SUM(D20:D24)+D25+D26 -> 0 | E27: =E17+E18+E19+SUM(E20:E24)+E25+E26 -> 3628284.1 | F27: =F17+F18+F19+SUM(F20:F24)+F25+F26 -> 46685528 | G27: =G17+G18+G19+SUM(G20:G24)+G25+G26 -> 2.514566e+08 | H27: =H17+H18+H19+SUM(H20:H24)+H25+H26 -> 1.9504544e+08 | I27: =I17+I18+I19+SUM(I20:I24)+I25+I26 -> 1.0426245e+08 | J27: =J17+J18+J19+SUM(J20:J24)+J25+J26 -> 75999625 | ... N27: =N17+N18+N19+SUM(N20:N24)+N25+N26 -> 63360593
B32: Punto de Equilibrio
B33: Gastos Fijos Mensuales Proyectados | M33: ='Costos Fijos'!P4 -> 8329123.3 | N33: ='Costos Fijos'!Q4 -> 8329123.3
B34: Margen Bruto objetivo | M34: 0.2 | N34: 0.2
B35: Ventas Miinimas Requeridas | M35: =M33/M34 -> 41645617 | N35: =N33/N34 -> 41645617
B36: Costo de Ventas Implicito | M36: =M35*(1-M34) -> 33316493 | N36: =N35*(1-N34) -> 33316493
B39: Check
B40: Suma de todos los movimientos | C40: =SUM('Extractos bancarios - Manglar'!$C:$C) -> 63360593
B41: Capturado por el flujo de caja | C41: =SUM(C18:N24)+SUM(C25:N26) -> 63360593
B42: Diferencia (debe ser 0) | C42: =C40-C41 -> 0
B43: Movimientos en cuenta "Revisar" | C43: =SUMIFS('Extractos bancarios - Manglar'!$C:$C,'Extractos bancarios - Manglar'!$G:$G,"Revisar") -> 0
B45: Ingresos facturados (P&G) | C45: =O4 -> 486681543
B46: Ingresos cobrados (neto de IVA) | C46: =(SUMIFS('Extractos bancarios - Manglar'!$C:$C,'Extractos bancarios - Manglar'!$G:$G,"Ingresos",'Extractos bancarios - Manglar'!$K:$K,"Si")/1.19)+SUMIFS('Extractos bancarios - Manglar'!$C:$C,'Extractos bancarios - Manglar'!$G:$G,"Ingresos",'Extractos bancarios - Manglar'!$K:$K,"No")+SUMIFS('Extractos bancarios - Manglar'!$C:$C,'Extractos bancarios - Manglar'!$G:$G,"Ingresos",'Extractos bancarios - Manglar'!$K:$K,"NA") -> 4.5509889e+08
B47: Diferencia (cartera y retenciones) | C47: =C45-C46 -> 31582650
B50: Cobertura de costos
B51: Costo total del P&G | C51: =O5+O9+O10+O11 -> -3.868378e+08
...

Sheet Extractos bancarios - Manglar
A1: Fecha | B1: Descripción banco | C1: Valor | D1: Categoría | E1: Descripción interna | F1: Mes Caja | G1: Cuenta | H1: Centro de costo | I1: Cliente | J1: Proyecto | K1: IVA? | L1: Mes (Causación P&G) | M1: Factura | N1: Comentarios | O1: Link | P1: https://docs.google.com/spreadsheets/d/18Om0REh-zkuZNfu-JHQBKEZbUhkMH-UE_ZbSgjpWadU/edit?gid=527771349#gid=527771349
A2: 46091 | B2: CONSIG LOCAL CAJ | C2: 2000000 | D2: Abono capital | E2: Abono Juan David | F2: 3 | G2: =IFERROR(VLOOKUP(D2,Data!$A:$B,2,0),"Revisar") -> Otros Ingresos | H2: NA | I2: {=_xlfn.XLOOKUP($H2,Data!$E:$E,Data!$F:$F,"Revisar",0)} -> NA | J2: {=_xlfn.XLOOKUP($H2,Data!$E:$E,Data!$G:$G,"Revisar",0)} -> NA | K2: No
A3: 46093 | B3: ABONO INTERESES AHORROS | C3: 8.19 | D3: Intereses | E3: Intereses | F3: 3 | G3: =IFERROR(VLOOKUP(D3,Data!$A:$B,2,0),"Revisar") -> Gastos Variables | H3: NA | I3: {=_xlfn.XLOOKUP($H3,Data!$E:$E,Data!$F:$F,"Revisar",0)} -> NA | J3: {=_xlfn.XLOOKUP($H3,Data!$E:$E,Data!$G:$G,"Revisar",0)} -> NA | K3: NA | L3: =F3 -> 3
A4: 46093 | B4: MANEJO TARJETA DEB 03 26 | C4: -18050 | D4: Cuota de manejo | E4: Cuota de manejo | F4: 3 | G4: =IFERROR(VLOOKUP(D4,Data!$A:$B,2,0),"Revisar") -> Costos Fijos | H4: NA | I4: {=_xlfn.XLOOKUP($H4,Data!$E:$E,Data!$F:$F,"Revisar",0)} -> NA | J4: {=_xlfn.XLOOKUP($H4,Data!$E:$E,Data!$G:$G,"Revisar",0)} -> NA | K4: NA | L4: =F4 -> 3
A5: 46093 | B5: AJUSTE INTERES AHORROS DB | C5: -0.02 | D5: Intereses | E5: Intereses | F5: 3 | G5: =IFERROR(VLOOKUP(D5,Data!$A:$B,2,0),"Revisar") -> Gastos Variables | H5: NA | I5: {=_xlfn.XLOOKUP($H5,Data!$E:$E,Data!$F:$F,"Revisar",0)} -> NA | J5: {=_xlfn.XLOOKUP($H5,Data!$E:$E,Data!$G:$G,"Revisar",0)} -> NA | K5: NA | L5: =F5 -> 3
A6: 46099 | B6: ABONO INTERESES AHORROS | C6: 16.26 | D6: Intereses | E6: Intereses | F6: 3 | G6: =IFERROR(VLOOKUP(D6,Data!$A:$B,2,0),"Revisar") -> Gastos Variables | H6: NA | I6: {=_xlfn.XLOOKUP($H6,Data!$E:$E,Data!$F:$F,"Revisar",0)} -> NA | J6: {=_xlfn.XLOOKUP($H6,Data!$E:$E,Data!$G:$G,"Revisar",0)} -> NA | K6: NA | L6: =F6 -> 3
A7: 46100 | B7: COMPRA EN EL ALTILLO | C7: -96100 | D7: Gastos representación | E7: Desayuno Kaspersky | F7: 3 | G7: =IFERROR(VLOOKUP(D7,Data!$A:$B,2,0),"Revisar") -> Costos Operacionales | I7: Kaspersky | J7: Gastos Representacion | K7: NA | L7: =F7 -> 3 | M7: FEST-4442
A8: 46104 | B8: ABONO INTERESES AHORROS | C8: 12.9 | D8: Intereses | E8: Intereses | F8: 3 | G8: =IFERROR(VLOOKUP(D8,Data!$A:$B,2,0),"Revisar") -> Gastos Variables | H8: NA | I8: {=_xlfn.XLOOKUP($H8,Data!$E:$E,Data!$F:$F,"Revisar",0)} -> NA | J8: {=_xlfn.XLOOKUP($H8,Data!$E:$E,Data!$G:$G,"Revisar",0)} -> NA | K8: NA | L8: =F8 -> 3
A9: 46104 | B9: SERVICIO TRANSFERENCIA VIRTUAL | C9: -7590 | D9: Costo transferencias | E9: Costo transferencias | F9: 3 | G9: =IFERROR(VLOOKUP(D9,Data!$A:$B,2,0),"Revisar") -> Gastos Variables | H9: NA | I9: {=_xlfn.XLOOKUP($H9,Data!$E:$E,Data!$F:$F,"Revisar",0)} -> NA | J9: {=_xlfn.XLOOKUP($H9,Data!$E:$E,Data!$G:$G,"Revisar",0)} -> NA | K9: NA | L9: =F9 -> 3
A10: 46104 | B10: TRANSFERENCIA VIRTUAL | C10: -748604 | D10: Servicios Prof | E10: Lexgra abogados | F10: 3 | G10: =IFERROR(VLOOKUP(D10,Data!$A:$B,2,0),"Revisar") -> Costos Operacionales | H10: NA | I10: {=_xlfn.XLOOKUP($H10,Data!$E:$E,Data!$F:$F,"Revisar",0)} -> NA | J10: {=_xlfn.XLOOKUP($H10,Data!$E:$E,Data!$G:$G,"Revisar",0)} -> NA | K10: NA | L10: =F10 -> 3 | M10: LXFE-420
A11: 46104 | B11: COBRO IVA PAGOS AUTOMATICOS | C11: -1442.1 | D11: IVA Descontable | E11: IVA Descontable | F11: 3 | G11: =IFERROR(VLOOKUP(D11,Data!$A:$B,2,0),"Revisar") -> Imp x Pagar - IVA | H11: NA | I11: {=_xlfn.XLOOKUP($H11,Data!$E:$E,Data!$F:$F,"Revisar",0)} -> NA | J11: {=_xlfn.XLOOKUP($H11,Data!$E:$E,Data!$G:$G,"Revisar",0)} -> NA | K11: NA | L11: =F11 -> 3
A12: 46106 | B12: ABONO INTERESES AHORROS | C12: 3.08 | D12: Intereses | E12: Intereses | F12: 3 | G12: =IFERROR(VLOOKUP(D12,Data!$A:$B,2,0),"Revisar") -> Gastos Variables | H12: NA | I12: {=_xlfn.XLOOKUP($H12,Data!$E:$E,Data!$F:$F,"Revisar",0)} -> NA | J12: {=_xlfn.XLOOKUP($H12,Data!$E:$E,Data!$G:$G,"Revisar",0)} -> NA | K12: NA | L12: =F12 -> 3
A13: 46107 | B13: TRANSFERENCIA CTA SUC VIRTUAL | C13: 2500000 | D13: Abono capital | E13: Abono Veronica | F13: 3 | G13: =IFERROR(VLOOKUP(D13,Data!$A:$B,2,0),"Revisar") -> Otros Ingresos | H13: NA | I13: {=_xlfn.XLOOKUP($H13,Data!$E:$E,Data!$F:$F,"Revisar",0)} -> NA | J13: {=_xlfn.XLOOKUP($H13,Data!$E:$E,Data!$G:$G,"Revisar",0)} -> NA | K13: No
A14: 46112 | B14: ABONO INTERESES AHORROS | C14: 29.82 | D14: Intereses | E14: Intereses | F14: 3 | G14: =IFERROR(VLOOKUP(D14,Data!$A:$B,2,0),"Revisar") -> Gastos Variables | H14: NA | I14: {=_xlfn.XLOOKUP($H14,Data!$E:$E,Data!$F:$F,"Revisar",0)} -> NA | J14: {=_xlfn.XLOOKUP($H14,Data!$E:$E,Data!$G:$G,"Revisar",0)} -> NA | K14: NA | L14: =F14 -> 3
A15: 46142 | B15: ABONO INTERESES AHORROS | C15: 255.64 | D15: Intereses | E15: Intereses | F15: 4 | G15: =IFERROR(VLOOKUP(D15,Data!$A:$B,2,0),"Revisar") -> Gastos Variables | H15: NA | I15: {=_xlfn.XLOOKUP($H15,Data!$E:$E,Data!$F:$F,"Revisar",0)} -> NA | J15: {=_xlfn.XLOOKUP($H15,Data!$E:$E,Data!$G:$G,"Revisar",0)} -> NA | K15: NA | L15: =F15 -> 4
A16: 46139 | B16: TRANSFERENCIA CTA SUC VIRTUAL | C16: -728875 | D16: Pago proveedores | E16: Smart Design - Innovaitors | F16: 4 | G16: =IFERROR(VLOOKUP(D16,Data!$A:$B,2,0),"Revisar") -> Costo Ventas | H16: M260301 | I16: {=_xlfn.XLOOKUP($H16,Data!$E:$E,Data!$F:$F,"Revisar",0)} -> Innovaitors | J16: {=_xlfn.XLOOKUP($H16,Data!$E:$E,Data!$G:$G,"Revisar",0)} -> Kits Innovaitors | K16: Si | L16: =F16 -> 4 | M16: SD-404
A17: 46138 | B17: ABONO INTERESES AHORROS | C17: 194.7 | D17: Intereses | E17: Intereses | F17: 4 | G17: =IFERROR(VLOOKUP(D17,Data!$A:$B,2,0),"Revisar") -> Gastos Variables | H17: NA | I17: {=_xlfn.XLOOKUP($H17,Data!$E:$E,Data!$F:$F,"Revisar",0)} -> NA | J17: {=_xlfn.XLOOKUP($H17,Data!$E:$E,Data!$G:$G,"Revisar",0)} -> NA | K17: NA | L17: =F17 -> 4
A18: 46136 | B18: COBRO IVA PAGOS AUTOMATICOS | C18: -1442.1 | D18: IVA Descontable | E18: IVA Descontable | F18: 4 | G18: =IFERROR(VLOOKUP(D18,Data!$A:$B,2,0),"Revisar") -> Imp x Pagar - IVA | H18: NA | I18: {=_xlfn.XLOOKUP($H18,Data!$E:$E,Data!$F:$F,"Revisar",0)} -> NA | J18: {=_xlfn.XLOOKUP($H18,Data!$E:$E,Data!$G:$G,"Revisar",0)} -> NA | K18: NA | L18: =F18 -> 4
A19: 46136 | B19: COBRO IVA PAGOS AUTOMATICOS | C19: -1442.1 | D19: IVA Descontable | E19: IVA Descontable | F19: 4 | G19: =IFERROR(VLOOKUP(D19,Data!$A:$B,2,0),"Revisar") -> Imp x Pagar - IVA | H19: NA | I19: {=_xlfn.XLOOKUP($H19,Data!$E:$E,Data!$F:$F,"Revisar",0)} -> NA | J19: {=_xlfn.XLOOKUP($H19,Data!$E:$E,Data!$G:$G,"Revisar",0)} -> NA | K19: NA | L19: =F19 -> 4
A20: 46136 | B20: TRANSFERENCIA VIRTUAL | C20: -38000 | D20: Pago proveedores | E20: KAS - Vasos | F20: 4 | G20: =IFERROR(VLOOKUP(D20,Data!$A:$B,2,0),"Revisar") -> Costo Ventas | H20: M260201 | I20: {=_xlfn.XLOOKUP($H20,Data!$E:$E,Data!$F:$F,"Revisar",0)} -> Konrad Adenauer Stiftung | J20: {=_xlfn.XLOOKUP($H20,Data!$E:$E,Data!$G:$G,"Revisar",0)} -> Material KAS - Tacos y pocillos | K20: Si | L20: =F20 -> 4 | M20: AOG-810
A21: 46136 | B21: TRANSFERENCIA VIRTUAL | C21: -200000 | D21: Pago proveedores | E21: KAS - Vasos | F21: 4 | G21: =IFERROR(VLOOKUP(D21,Data!$A:$B,2,0),"Revisar") -> Costo Ventas | H21: M260201 | I21: {=_xlfn.XLOOKUP($H21,Data!$E:$E,Data!$F:$F,"Revisar",0)} -> Konrad Adenauer Stiftung | J21: {=_xlfn.XLOOKUP($H21,Data!$E:$E,Data!$G:$G,"Revisar",0)} -> Material KAS - Tacos y pocillos | K21: Si | L21: =F21 -> 4 | M21: AOG-810
A22: 46136 | B22: SERVICIO TRANSFERENCIA VIRTUAL | C22: 7590 | D22: Costo transferencias | E22: Comisión transferencia | F22: 4 | G22: =IFERROR(VLOOKUP(D22,Data!$A:$B,2,0),"Revisar") -> Gastos Variables | H22: NA | I22: {=_xlfn.XLOOKUP($H22,Data!$E:$E,Data!$F:$F,"Revisar",0)} -> NA | J22: {=_xlfn.XLOOKUP($H22,Data!$E:$E,Data!$G:$G,"Revisar",0)} -> NA | K22: NA | L22: =F22 -> 4
A23: 46136 | B23: SERVICIO TRANSFERENCIA VIRTUAL | C23: 7590 | D23: Costo transferencias | E23: Comisión transferencia | F23: 4 | G23: =IFERROR(VLOOKUP(D23,Data!$A:$B,2,0),"Revisar") -> Gastos Variables | H23: NA | I23: {=_xlfn.XLOOKUP($H23,Data!$E:$E,Data!$F:$F,"Revisar",0)} -> NA | J23: {=_xlfn.XLOOKUP($H23,Data!$E:$E,Data!$G:$G,"Revisar",0)} -> NA | K23: NA | L23: =F23 -> 4
A24: 46135 | B24: ABONO INTERESES AHORROS | C24: 65.25 | D24: Intereses | E24: Intreses | F24: 4 | G24: =IFERROR(VLOOKUP(D24,Data!$A:$B,2,0),"Revisar") -> Gastos Variables | H24: NA | I24: {=_xlfn.XLOOKUP($H24,Data!$E:$E,Data!$F:$F,"Revisar",0)} -> NA | J24: {=_xlfn.XLOOKUP($H24,Data!$E:$E,Data!$G:$G,"Revisar",0)} -> NA | K24: NA | L24: =F24 -> 4
A25: 46135 | B25: PAGO INTERBANC Axis Communicat | C25: 37014469 | D25: Pago clientes | E25: Axis | F25: 4 | G25: =IFERROR(VLOOKUP(D25,Data!$A:$B,2,0),"Revisar") -> Ingresos | H25: M260101 | I25: {=_xlfn.XLOOKUP($H25,Data!$E:$E,Data!$F:$F,"Revisar",0)} -> AXIS | J25: {=_xlfn.XLOOKUP($H25,Data!$E:$E,Data!$G:$G,"Revisar",0)} -> Evento mundial de fútbol y merchandising | K25: Si | L25: 6 | M25: DAFE 1
A26: 46135 | B26: TRANSFERENCIA CTA SUC VIRTUAL | C26: -728875 | D26: Pago proveedores | E26: Smart Design - Innovaitors | F26: 4 | G26: =IFERROR(VLOOKUP(D26,Data!$A:$B,2,0),"Revisar") -> Costo Ventas | H26: M260301 | I26: {=_xlfn.XLOOKUP($H26,Data!$E:$E,Data!$F:$F,"Revisar",0)} -> Innovaitors | J26: {=_xlfn.XLOOKUP($H26,Data!$E:$E,Data!$G:$G,"Revisar",0)} -> Kits Innovaitors | K26: Si | L26: =F26 -> 4 | M26: SD-404
A27: 46134 | B27: ABONO INTERESES AHORROS | C27: 31.1 | D27: Intereses | E27: Intreses | F27: 4 | G27: =IFERROR(VLOOKUP(D27,Data!$A:$B,2,0),"Revisar") -> Gastos Variables | H27: NA | I27: {=_xlfn.XLOOKUP($H27,Data!$E:$E,Data!$F:$F,"Revisar",0)} -> NA | J27: {=_xlfn.XLOOKUP($H27,Data!$E:$E,Data!$G:$G,"Revisar",0)} -> NA | K27: NA | L27: =F27 -> 4
A28: 46133 | B28: COBRO IVA PAGOS AUTOMATICOS | C28: -1442.1 | D28: IVA Descontable | E28: IVA Descontable | F28: 4 | G28: =IFERROR(VLOOKUP(D28,Data!$A:$B,2,0),"Revisar") -> Imp x Pagar - IVA | H28: NA | I28: {=_xlfn.XLOOKUP($H28,Data!$E:$E,Data!$F:$F,"Revisar",0)} -> NA | J28: {=_xlfn.XLOOKUP($H28,Data!$E:$E,Data!$G:$G,"Revisar",0)} -> NA | K28: NA | L28: =F28 -> 4
A29: 46133 | B29: SERVICIO TRANSFERENCIA VIRTUAL | C29: -7590 | D29: Costo transferencias | E29: Intreses | F29: 4 | G29: =IFERROR(VLOOKUP(D29,Data!$A:$B,2,0),"Revisar") -> Gastos Variables | H29: NA | I29: {=_xlfn.XLOOKUP($H29,Data!$E:$E,Data!$F:$F,"Revisar",0)} -> NA | J29: {=_xlfn.XLOOKUP($H29,Data!$E:$E,Data!$G:$G,"Revisar",0)} -> NA | K29: NA | L29: =F29 -> 4
